Workbook

Sheet PM
B3: Postazione di analisi n. 1 | C3: Condizione di misura
B4: SORGENTI DI RUMORE (Macchinari/Attrezzature utilizzate e/o in funzione ) | C4: Misura 1 | D4: Attrezzature di lavoro e/o rumore di fondo ambientale | R4: =B10 -> 0
C5: Misura 2 | D5: Attrezzature di lavoro e/o rumore di fondo ambientale | R5: TEMPO TOTALE
C6: Misura 3 | D6: Attrezzature di lavoro e/o rumore di fondo ambientale | R6: =D16+D32+D48+D64+D80+D96+D112+D128+D144+D160+D176+D192+D208+D224+D240+D256+D272+D288+D304+D320+D336+D352+D368+D384+D400+D416+D432+D448+D464+D480 -> 0 | S6: = | T6: =R6*60 -> 0
R7: ore | T7: minuti
B8: Lavoratori esposti | D8: Esposiz. giorno | F8: Risultati misure | N8: LAeq,mi
B9: Gruppo Omogeneo | D9: Tm,j [min] | F9: LAeq,mi | G9: dBA | H9: LCeq,mi | I9: dBC | J9: Lpicco,mi | K9: dBC | R9: CONVERTITORE DA ORE A MINUTI
D10: =IF(D14<380, 1.1*D14, D14) -> 0 | F10: LAeq,m1 | G10: =N9*0.998 -> 0 | H10: LCeq,m1 | I10: =N11*1.002 -> 0 | J10: Lpicco,m1 | K10: =N13*1.001 -> 0 | N10: LCeq,mi | S10: = | T10: =R10*60 -> 0
D11: =IF(D14<380, 0.75*D14, D14) -> 0 | F11: LAeq,m2 | G11: =N9*1.003 -> 0 | H11: LCeq,m2 | I11: =N11*0.999 -> 0 | J11: Lpicco,m2 | K11: =N13*0.995 -> 0 | R11: ore | T11: minuti
D12: =IF(D14<380, 1.15*D14, D14) -> 0 | F12: LAeq,m3 | G12: =N9*0.996 -> 0 | H12: LCeq,m3 | I12: =N11*1.004 -> 0 | J12: Lpicco,m3 | K12: =N13*0.997 -> 0 | N12: Lpicco,mi
D13: Tm [min] | F13: LAeq,m | G13: =10*LOG10((1/3)*(10^(0.1*G10)+10^(0.1*G11)+10^(0.1*G12))) -> 0 | H13: LCeq,m | I13: =10*LOG10((1/3)*(10^(0.1*I10)+10^(0.1*I11)+10^(0.1*I12))) -> 0 | J13: Lpicco,m | K13: =(K10+K11+K12)/3 -> 0 | R13: CONVERTITORE DA MINUTI AD ORE
S14: = | T14: =R14/60 -> 0
D15: Tm [ore] | R15: minuti | T15: ore
D16: =D14/60 -> 0
B19: Postazione di analisi n. 2 | C19: Condizione di misura
B20: SORGENTI DI RUMORE (Macchinari/Attrezzature utilizzate e/o in funzione ) | C20: Misura 1 | D20: Attrezzature di lavoro e/o rumore di fondo ambientale
C21: Misura 2 | D21: Attrezzature di lavoro e/o rumore di fondo ambientale
C22: Misura 3 | D22: Attrezzature di lavoro e/o rumore di fondo ambientale
B24: Lavoratori esposti | D24: Esposiz. giorno | F24: Risultati misure | N24: LAeq,mi
B25: Gruppo Omogeneo | D25: Tm,j [min] | F25: LAeq,mi | G25: dBA | H25: LCeq,mi | I25: dBC | J25: Lpicco,mi | K25: dBC
B26: =B10 -> 0 | D26: =IF(D30<380, 0.9*D30, D30) -> 0 | F26: LAeq,m1 | G26: =N25*0.997 -> 0 | H26: LCeq,m1 | I26: =N27*1.003 -> 0 | J26: Lpicco,m1 | K26: =N29*0.998 -> 0 | N26: LCeq,mi
D27: =IF(D30<380, 1.25*D30, D30) -> 0 | F27: LAeq,m2 | G27: =N25*0.999 -> 0 | H27: LCeq,m2 | I27: =N27*0.995 -> 0 | J27: Lpicco,m2 | K27: =N29*1.002 -> 0
D28: =IF(D30<380, 0.85*D30, D30) -> 0 | F28: LAeq,m3 | G28: =N25*1.002 -> 0 | H28: LCeq,m3 | I28: =N27*1.001 -> 0 | J28: Lpicco,m3 | K28: =N29*0.999 -> 0 | N28: Lpicco,mi
D29: Tm [min] | F29: LAeq,m | G29: =10*LOG10((1/3)*(10^(0.1*G26)+10^(0.1*G27)+10^(0.1*G28))) -> 0 | H29: LCeq,m | I29: =10*LOG10((1/3)*(10^(0.1*I26)+10^(0.1*I27)+10^(0.1*I28))) -> 0 | J29: Lpicco,m | K29: =(K26+K27+K28)/3 -> 0
D31: Tm [ore]
D32: =D30/60 -> 0
B35: Postazione di analisi n. 3 | C35: Condizione di misura
B36: SORGENTI DI RUMORE (Macchinari/Attrezzature utilizzate e/o in funzione ) | C36: Misura 1 | D36: Attrezzature di lavoro e/o rumore di fondo ambientale
C37: Misura 2 | D37: Attrezzature di lavoro e/o rumore di fondo ambientale
C38: Misura 3 | D38: Attrezzature di lavoro e/o rumore di fondo ambientale
B40: Lavoratori esposti | D40: Esposiz. giorno | F40: Risultati misure | N40: LAeq,mi
B41: Gruppo Omogeneo | D41: Tm,j [min] | F41: LAeq,mi | G41: dBA | H41: LCeq,mi | I41: dBC | J41: Lpicco,mi | K41: dBC
B42: =B26 -> 0 | D42: =IF(D46<380, 0.8*D46, D46) -> 0 | F42: LAeq,m1 | G42: =N41*1.004 -> 0 | H42: LCeq,m1 | I42: =N43*0.997 -> 0 | J42: Lpicco,m1 | K42: =N45*0.996 -> 0 | N42: LCeq,mi
D43: =IF(D46<380, 1.05*D46, D46) -> 0 | F43: LAeq,m2 | G43: =N41*0.998 -> 0 | H43: LCeq,m2 | I43: =N43*0.999 -> 0 | J43: Lpicco,m2 | K43: =N45*1.003 -> 0
D44: =IF(D46<380, 1.15*D46, D46) -> 0 | F44: LAeq,m3 | G44: =N41*1.002 -> 0 | H44: LCeq,m3 | I44: =N43*1.003 -> 0 | J44: Lpicco,m3 | K44: =N45*1.001 -> 0 | N44: Lpicco,mi
D45: Tm [min] | F45: LAeq,m | G45: =10*LOG10((1/3)*(10^(0.1*G42)+10^(0.1*G43)+10^(0.1*G44))) -> 0 | H45: LCeq,m | I45: =10*LOG10((1/3)*(10^(0.1*I42)+10^(0.1*I43)+10^(0.1*I44))) -> 0 | J45: Lpicco,m | K45: =(K42+K43+K44)/3 -> 0
D47: Tm [ore]
D48: =D46/60 -> 0
B51: Postazione di analisi n. 4 | C51: Condizione di misura
B52: SORGENTI DI RUMORE (Macchinari/Attrezzature utilizzate e/o in funzione ) | C52: Misura 1 | D52: Attrezzature di lavoro e/o rumore di fondo ambientale
...

Sheet Calcolo incertezza U(LEX,8h)
E2: LEX,8h [dBA] | F2: =10*LOG10(((PM!D16/8)*10^(0.1*PM!G13))+((PM!D32/8)*10^(0.1*PM!G29))+((PM!D48/8)*10^(0.1*PM!G45))+((PM!D64/8)*10^(0.1*PM!G61))+((PM!D80/8)*10^(0.1*PM!G77))+((PM!D96/8)*10^(0.1*PM!G93))+((PM!D112/8)*10^(0.1*PM!G109))+((PM!D128/8)*10^(0.1*PM!G125))+((PM!D144/8)*10^(0.1*PM!G141))+((PM!D160/8)*10^(0.1*PM!G157))+((PM!D176/8)*10^(0.1*PM!G173))+((PM!D192/8)*10^(0.1*PM!G189))+((PM!D208/8)*10^(0.1*PM!G205))+((PM!D224/8)*10^(0.1*PM!G221))+((PM!D240/8)*10^(0.1*PM!G237))+((PM!D256/8)*10^(0.1*PM!G253))+((PM!D272/8)*10^(0.1*PM!G269))+((PM!D288/8)*10^(0.1*PM!G285))+((PM!D304/8)*10^(0.1*PM!G301))+((PM!D320/8)*10^(0.1*PM!G317))+((PM!D336/8)*10^(0.1*PM!G333))+((PM!D352/8)*10^(0.1*PM!G349))+((PM!D368/8)*10^(0.1*PM!G365))+((PM!D384/8)*10^(0.1*PM!G381))+((PM!D400/8)*10^(0.1*PM!G397))+((PM!D416/8)*10^(0.1*PM!G413))+((PM!D432/8)*10^(0.1*PM!G429))+((PM!D448/8)*10^(0.1*PM!G445))+((PM!D464/8)*10^(0.1*PM!G461))+((PM!D480/8)*10^(0.1*PM!G477))) -> #NUM!
E3: Gruppo omogeneo | F3: =PM!B10 -> 0
E4: Attrezzature di lavoro e/o rumore di fondo ambientale | F4: Tm [ore] | G4: LAeq,m [dBA] | H4: Lpicco,m [dBC] | I4: C1a,m | J4: C1b,m | K4: Laeq medio [dBA] | L4: U1a,m [dBA] | M4: U1b,m [dBA] | N4: U2,m [dBA] | O4: U3 [dBA]
D5: 1 | E5: =PM!D3 -> 0 | F5: =PM!D16 -> 0 | G5: =PM!G13 -> 0 | H5: =PM!K13 -> 0 | I5: =((F5/8)*10^(0.1*(G5-F2))) -> #NUM! | J5: =4.34*(I5/F5) -> #NUM! | K5: =(PM!G10+PM!G11+PM!G12)/3 -> 0 | L5: =SQRT((1/6)*((PM!G10-K5)^2+(PM!G11-K5)^2+(PM!G12-K5)^2)) -> 0 | M5: =SQRT((1/6)*(((PM!D10/60)-F5)^2+((PM!D11/60)-F5)^2+((PM!D12/60)-F5)^2)) -> 0 | N5: 0.7 | O5: 1 | Q5: =(I5^2)*((L5^2)+(N5^2)+(O5^2))+((J5*M5)^2) -> #NUM! | R5: =IFERROR(Q5,0) -> 0
D6: 2 | E6: =PM!D19 -> 0 | F6: =PM!D32 -> 0 | G6: =PM!G29 -> 0 | H6: =PM!K29 -> 0 | I6: =((F6/8)*10^(0.1*(G6-F2))) -> #NUM! | J6: =4.34*(I6/F6) -> #NUM! | K6: =(PM!G26+PM!G27+PM!G28)/3 -> 0 | L6: =SQRT((1/6)*((PM!G26-K6)^2+(PM!G27-K6)^2+(PM!G28-K6)^2)) -> 0 | M6: =SQRT((1/6)*(((PM!D26/60)-F6)^2+((PM!D27/60)-F6)^2+((PM!D28/60)-F6)^2)) -> 0 | N6: 0.7 | O6: 1 | Q6: =(I6^2)*((L6^2)+(N6^2)+(O6^2))+((J6*M6)^2) -> #NUM! | R6: =IFERROR(Q6,0) -> 0
D7: 3 | E7: =PM!D35 -> 0 | F7: =PM!D48 -> 0 | G7: =PM!G45 -> 0 | H7: =PM!K45 -> 0 | I7: =((F7/8)*10^(0.1*(G7-F2))) -> #NUM! | J7: =4.34*(I7/F7) -> #NUM! | K7: =(PM!G42+PM!G43+PM!G44)/3 -> 0 | L7: =SQRT((1/6)*((PM!G42-K7)^2+(PM!G43-K7)^2+(PM!G44-K7)^2)) -> 0 | M7: =SQRT((1/6)*(((PM!D42/60)-F7)^2+((PM!D43/60)-F7)^2+((PM!D44/60)-F7)^2)) -> 0 | N7: 0.7 | O7: 1 | Q7: =(I7^2)*((L7^2)+(N7^2)+(O7^2))+((J7*M7)^2) -> #NUM! | R7: =IFERROR(Q7,0) -> 0
D8: 4 | E8: =PM!D51 -> 0 | F8: =PM!D64 -> 0 | G8: =PM!G61 -> 0 | H8: =PM!K61 -> 0 | I8: =((F8/8)*10^(0.1*(G8-F2))) -> #NUM! | J8: =4.34*(I8/F8) -> #NUM! | K8: =(PM!G58+PM!G59+PM!G60)/3 -> 0 | L8: =SQRT((1/6)*((PM!G58-K8)^2+(PM!G59-K8)^2+(PM!G60-K8)^2)) -> 0 | M8: =SQRT((1/6)*(((PM!D58/60)-F8)^2+((PM!D59/60)-F8)^2+((PM!D60/60)-F8)^2)) -> 0 | N8: 0.7 | O8: 1 | Q8: =(I8^2)*((L8^2)+(N8^2)+(O8^2))+((J8*M8)^2) -> #NUM! | R8: =IFERROR(Q8,0) -> 0
D9: 5 | E9: =PM!D67 -> 0 | F9: =PM!D80 -> 0 | G9: =PM!G77 -> 0 | H9: =PM!K77 -> 0 | I9: =((F9/8)*10^(0.1*(G9-F2))) -> #NUM! | J9: =4.34*(I9/F9) -> #NUM! | K9: =(PM!G74+PM!G75+PM!G76)/3 -> 0 | L9: =SQRT((1/6)*((PM!G74-K9)^2+(PM!G75-K9)^2+(PM!G76-K9)^2)) -> 0 | M9: =SQRT((1/6)*(((PM!D74/60)-F9)^2+((PM!D75/60)-F9)^2+((PM!D76/60)-F9)^2)) -> 0 | N9: 0.7 | O9: 1 | Q9: =(I9^2)*((L9^2)+(N9^2)+(O9^2))+((J9*M9)^2) -> #NUM! | R9: =IFERROR(Q9,0) -> 0
D10: 6 | E10: =PM!D83 -> 0 | F10: =PM!D96 -> 0 | G10: =PM!G93 -> 0 | H10: =PM!K93 -> 0 | I10: =((F10/8)*10^(0.1*(G10-F2))) -> #NUM! | J10: =4.34*(I10/F10) -> #NUM! | K10: =(PM!G90+PM!G91+PM!G92)/3 -> 0 | L10: =SQRT((1/6)*((PM!G90-K10)^2+(PM!G91-K10)^2+(PM!G92-K10)^2)) -> 0 | M10: =SQRT((1/6)*(((PM!D90/60)-F10)^2+((PM!D91/60)-F10)^2+((PM!D92/60)-F10)^2)) -> 0 | N10: 0.7 | O10: 1 | Q10: =(I10^2)*((L10^2)+(N10^2)+(O10^2))+((J10*M10)^2) -> #NUM! | R10: =IFERROR(Q10,0) -> 0
D11: 7 | E11: =PM!D99 -> 0 | F11: =PM!D112 -> 0 | G11: =PM!G109 -> 0 | H11: =PM!K109 -> 0 | I11: =((F11/8)*10^(0.1*(G11-F2))) -> #NUM! | J11: =4.34*(I11/F11) -> #NUM! | K11: =(PM!G106+PM!G107+PM!G108)/3 -> 0 | L11: =SQRT((1/6)*((PM!G106-K11)^2+(PM!G107-K11)^2+(PM!G108-K11)^2)) -> 0 | M11: =SQRT((1/6)*(((PM!D106/60)-F11)^2+((PM!D107/60)-F11)^2+((PM!D108/60)-F11)^2)) -> 0 | N11: 0.7 | O11: 1 | Q11: =(I11^2)*((L11^2)+(N11^2)+(O11^2))+((J11*M11)^2) -> #NUM! | R11: =IFERROR(Q11,0) -> 0
D12: 8 | E12: =PM!D115 -> 0 | F12: =PM!D128 -> 0 | G12: =PM!G125 -> 0 | H12: =PM!K125 -> 0 | I12: =((F12/8)*10^(0.1*(G12-F2))) -> #NUM! | J12: =4.34*(I12/F12) -> #NUM! | K12: =(PM!G122+PM!G123+PM!G124)/3 -> 0 | L12: =SQRT((1/6)*((PM!G122-K12)^2+(PM!G123-K12)^2+(PM!G124-K12)^2)) -> 0 | M12: =SQRT((1/6)*(((PM!D122/60)-F12)^2+((PM!D123/60)-F12)^2+((PM!D124/60)-F12)^2)) -> 0 | N12: 0.7 | O12: 1 | Q12: =(I12^2)*((L12^2)+(N12^2)+(O12^2))+((J12*M12)^2) -> #NUM! | R12: =IFERROR(Q12,0) -> 0
D13: 9 | E13: =PM!D131 -> 0 | F13: =PM!D144 -> 0 | G13: =PM!G141 -> 0 | H13: =PM!K141 -> 0 | I13: =((F13/8)*10^(0.1*(G13-F2))) -> #NUM! | J13: =4.34*(I13/F13) -> #NUM! | K13: =(PM!G138+PM!G139+PM!G140)/3 -> 0 | L13: =SQRT((1/6)*((PM!G138-K13)^2+(PM!G139-K13)^2+(PM!G140-K13)^2)) -> 0 | M13: =SQRT((1/6)*(((PM!D138/60)-F13)^2+((PM!D139/60)-F13)^2+((PM!D140/60)-F13)^2)) -> 0 | N13: 0.7 | O13: 1 | Q13: =(I13^2)*((L13^2)+(N13^2)+(O13^2))+((J13*M13)^2) -> #NUM! | R13: =IFERROR(Q13,0) -> 0
D14: 10 | E14: =PM!D147 -> 0 | F14: =PM!D160 -> 0 | G14: =PM!G157 -> 0 | H14: =PM!K157 -> 0 | I14: =((F14/8)*10^(0.1*(G14-F2))) -> #NUM! | J14: =4.34*(I14/F14) -> #NUM! | K14: =(PM!G154+PM!G155+PM!G156)/3 -> 0 | L14: =SQRT((1/6)*((PM!G154-K14)^2+(PM!G155-K14)^2+(PM!G156-K14)^2)) -> 0 | M14: =SQRT((1/6)*(((PM!D154/60)-F14)^2+((PM!D155/60)-F14)^2+((PM!D156/60)-F14)^2)) -> 0 | N14: 0.7 | O14: 1 | Q14: =(I14^2)*((L14^2)+(N14^2)+(O14^2))+((J14*M14)^2) -> #NUM! | R14: =IFERROR(Q14,0) -> 0
D15: 11 | E15: =PM!D163 -> 0 | F15: =PM!D176 -> 0 | G15: =PM!G173 -> 0 | H15: =PM!K173 -> 0 | I15: =((F15/8)*10^(0.1*(G15-F2))) -> #NUM! | J15: =4.34*(I15/F15) -> #NUM! | K15: =(PM!G170+PM!G171+PM!G172)/3 -> 0 | L15: =SQRT((1/6)*((PM!G170-K15)^2+(PM!G171-K15)^2+(PM!G172-K15)^2)) -> 0 | M15: =SQRT((1/6)*(((PM!D170/60)-F15)^2+((PM!D171/60)-F15)^2+((PM!D172/60)-F15)^2)) -> 0 | N15: 0.7 | O15: 1 | Q15: =((I15^2)*((L15^2)+(N15^2)+(O15^2)+((J15*M15)^2))) -> #NUM! | R15: =IFERROR(Q15,0) -> 0
D16: 12 | E16: =PM!D179 -> 0 | F16: =PM!D192 -> 0 | G16: =PM!G189 -> 0 | H16: =PM!K189 -> 0 | I16: =((F16/8)*10^(0.1*(G16-F2))) -> #NUM! | J16: =4.34*(I16/F16) -> #NUM! | K16: =(PM!G186+PM!G187+PM!G188)/3 -> 0 | L16: =SQRT((1/6)*((PM!G186-K16)^2+(PM!G187-K16)^2+(PM!G188-K16)^2)) -> 0 | M16: =SQRT((1/6)*(((PM!D186/60)-F16)^2+((PM!D187/60)-F16)^2+((PM!D188/60)-F16)^2)) -> 0 | N16: 0.7 | O16: 1 | Q16: =((I16^2)*((L16^2)+(N16^2)+(O16^2)+((J16*M16)^2))) -> #NUM! | R16: =IFERROR(Q16,0) -> 0
D17: 13 | E17: =PM!D195 -> 0 | F17: =PM!D208 -> 0 | G17: =PM!G205 -> 0 | H17: =PM!K205 -> 0 | I17: =((F17/8)*10^(0.1*(G17-F2))) -> #NUM! | J17: =4.34*(I17/F17) -> #NUM! | K17: =(PM!G202+PM!G203+PM!G204)/3 -> 0 | L17: =SQRT((1/6)*((PM!G202-K17)^2+(PM!G203-K17)^2+(PM!G204-K17)^2)) -> 0 | M17: =SQRT((1/6)*(((PM!D202/60)-F17)^2+((PM!D203/60)-F17)^2+((PM!D204/60)-F17)^2)) -> 0 | N17: 0.7 | O17: 1 | Q17: =((I17^2)*((L17^2)+(N17^2)+(O17^2)+((J17*M17)^2))) -> #NUM! | R17: =IFERROR(Q17,0) -> 0
D18: 14 | E18: =PM!D211 -> 0 | F18: =PM!D224 -> 0 | G18: =PM!G221 -> 0 | H18: =PM!K221 -> 0 | I18: =((F18/8)*10^(0.1*(G18-F2))) -> #NUM! | J18: =4.34*(I18/F18) -> #NUM! | K18: =(PM!G218+PM!G219+PM!G220)/3 -> 0 | L18: =SQRT((1/6)*((PM!G218-K18)^2+(PM!G219-K18)^2+(PM!G220-K18)^2)) -> 0 | M18: =SQRT((1/6)*(((PM!D218/60)-F18)^2+((PM!D219/60)-F18)^2+((PM!D220/60)-F18)^2)) -> 0 | N18: 0.7 | O18: 1 | Q18: =((I18^2)*((L18^2)+(N18^2)+(O18^2)+((J18*M18)^2))) -> #NUM! | R18: =IFERROR(Q18,0) -> 0
D19: 15 | E19: =PM!D227 -> 0 | F19: =PM!D240 -> 0 | G19: =PM!G237 -> 0 | H19: =PM!K237 -> 0 | I19: =((F19/8)*10^(0.1*(G19-F2))) -> #NUM! | J19: =4.34*(I19/F19) -> #NUM! | K19: =(PM!G234+PM!G235+PM!G236)/3 -> 0 | L19: =SQRT((1/6)*((PM!G234-K19)^2+(PM!G235-K19)^2+(PM!G236-K19)^2)) -> 0 | M19: =SQRT((1/6)*(((PM!D234/60)-F19)^2+((PM!D235/60)-F19)^2+((PM!D236/60)-F19)^2)) -> 0 | N19: 0.7 | O19: 1 | Q19: =((I19^2)*((L19^2)+(N19^2)+(O19^2)+((J19*M19)^2))) -> #NUM! | R19: =IFERROR(Q19,0) -> 0
D20: 16 | E20: =PM!D243 -> 0 | F20: =PM!D256 -> 0 | G20: =PM!G253 -> 0 | H20: =PM!K253 -> 0 | I20: =((F20/8)*10^(0.1*(G20-F2))) -> #NUM! | J20: =4.34*(I20/F20) -> #NUM! | K20: =(PM!G250+PM!G251+PM!G252)/3 -> 0 | L20: =SQRT((1/6)*((PM!G250-K20)^2+(PM!G251-K20)^2+(PM!G252-K20)^2)) -> 0 | M20: =SQRT((1/6)*(((PM!D250/60)-F20)^2+((PM!D251/60)-F20)^2+((PM!D252/60)-F20)^2)) -> 0 | N20: 0.7 | O20: 1 | Q20: =((I20^2)*((L20^2)+(N20^2)+(O20^2)+((J20*M20)^2))) -> #NUM! | R20: =IFERROR(Q20,0) -> 0
D21: 17 | E21: =PM!D259 -> 0 | F21: =PM!D272 -> 0 | G21: =PM!G269 -> 0 | H21: =PM!K269 -> 0 | I21: =((F21/8)*10^(0.1*(G21-F2))) -> #NUM! | J21: =4.34*(I21/F21) -> #NUM! | K21: =(PM!G266+PM!G267+PM!G268)/3 -> 0 | L21: =SQRT((1/6)*((PM!G266-K21)^2+(PM!G267-K21)^2+(PM!G268-K21)^2)) -> 0 | M21: =SQRT((1/6)*(((PM!D266/60)-F21)^2+((PM!D267/60)-F21)^2+((PM!D268/60)-F21)^2)) -> 0 | N21: 0.7 | O21: 1 | Q21: =((I21^2)*((L21^2)+(N21^2)+(O21^2)+((J21*M21)^2))) -> #NUM! | R21: =IFERROR(Q21,0) -> 0
D22: 18 | E22: =PM!D275 -> 0 | F22: =PM!D288 -> 0 | G22: =PM!G285 -> 0 | H22: =PM!K285 -> 0 | I22: =((F22/8)*10^(0.1*(G22-F2))) -> #NUM! | J22: =4.34*(I22/F22) -> #NUM! | K22: =(PM!G282+PM!G283+PM!G284)/3 -> 0 | L22: =SQRT((1/6)*((PM!G282-K22)^2+(PM!G283-K22)^2+(PM!G284-K22)^2)) -> 0 | M22: =SQRT((1/6)*(((PM!D282/60)-F22)^2+((PM!D283/60)-F22)^2+((PM!D284/60)-F22)^2)) -> 0 | N22: 0.7 | O22: 1 | Q22: =((I22^2)*((L22^2)+(N22^2)+(O22^2)+((J22*M22)^2))) -> #NUM! | R22: =IFERROR(Q22,0) -> 0
D23: 19 | E23: =PM!D291 -> 0 | F23: =PM!D304 -> 0 | G23: =PM!G301 -> 0 | H23: =PM!K301 -> 0 | I23: =((F23/8)*10^(0.1*(G23-F2))) -> #NUM! | J23: =4.34*(I23/F23) -> #NUM! | K23: =(PM!G298+PM!G299+PM!G300)/3 -> 0 | L23: =SQRT((1/6)*((PM!G298-K23)^2+(PM!G299-K23)^2+(PM!G300-K23)^2)) -> 0 | M23: =SQRT((1/6)*(((PM!D298/60)-F23)^2+((PM!D299/60)-F23)^2+((PM!D300/60)-F23)^2)) -> 0 | N23: 0.7 | O23: 1 | Q23: =((I23^2)*((L23^2)+(N23^2)+(O23^2)+((J23*M23)^2))) -> #NUM! | R23: =IFERROR(Q23,0) -> 0
D24: 20 | E24: =PM!D307 -> 0 | F24: =PM!D320 -> 0 | G24: =PM!G317 -> 0 | H24: =PM!K317 -> 0 | I24: =((F24/8)*10^(0.1*(G24-F2))) -> #NUM! | J24: =4.34*(I24/F24) -> #NUM! | K24: =(PM!G314+PM!G315+PM!G316)/3 -> 0 | L24: =SQRT((1/6)*((PM!G314-K24)^2+(PM!G315-K24)^2+(PM!G316-K24)^2)) -> 0 | M24: =SQRT((1/6)*(((PM!D314/60)-F24)^2+((PM!D315/60)-F24)^2+((PM!D316/60)-F24)^2)) -> 0 | N24: 0.7 | O24: 1 | Q24: =((I24^2)*((L24^2)+(N24^2)+(O24^2)+((J24*M24)^2))) -> #NUM! | R24: =IFERROR(Q24,0) -> 0
D25: 21 | E25: =PM!D323 -> 0 | F25: =PM!D336 -> 0 | G25: =PM!G333 -> 0 | H25: =PM!K333 -> 0 | I25: =((F25/8)*10^(0.1*(G25-F2))) -> #NUM! | J25: =4.34*(I25/F25) -> #NUM! | K25: =(PM!G330+PM!G331+PM!G332)/3 -> 0 | L25: =SQRT((1/6)*((PM!G330-K25)^2+(PM!G331-K25)^2+(PM!G332-K25)^2)) -> 0 | M25: =SQRT((1/6)*(((PM!D330/60)-F25)^2+((PM!D331/60)-F25)^2+((PM!D332/60)-F25)^2)) -> 0 | N25: 0.7 | O25: 1 | Q25: =((I25^2)*((L25^2)+(N25^2)+(O25^2)+((J25*M25)^2))) -> #NUM! | R25: =IFERROR(Q25,0) -> 0
D26: 22 | E26: =PM!D339 -> 0 | F26: =PM!D352 -> 0 | G26: =PM!G349 -> 0 | H26: =PM!K349 -> 0 | I26: =((F26/8)*10^(0.1*(G26-F2))) -> #NUM! | J26: =4.34*(I26/F26) -> #NUM! | K26: =(PM!G346+PM!G347+PM!G348)/3 -> 0 | L26: =SQRT((1/6)*((PM!G346-K26)^2+(PM!G347-K26)^2+(PM!G348-K26)^2)) -> 0 | M26: =SQRT((1/6)*(((PM!D346/60)-F26)^2+((PM!D347/60)-F26)^2+((PM!D348/60)-F26)^2)) -> 0 | N26: 0.7 | O26: 1 | Q26: =((I26^2)*((L26^2)+(N26^2)+(O26^2)+((J26*M26)^2))) -> #NUM! | R26: =IFERROR(Q26,0) -> 0
D27: 23 | E27: =PM!D355 -> 0 | F27: =PM!D368 -> 0 | G27: =PM!D368 -> 0 | H27: =PM!K365 -> 0 | I27: =((F27/8)*10^(0.1*(G27-F2))) -> #NUM! | J27: =4.34*(I27/F27) -> #NUM! | K27: =(PM!G362+PM!G363+PM!G364)/3 -> 0 | L27: =SQRT((1/6)*((PM!G362-K27)^2+(PM!G363-K27)^2+(PM!G364-K27)^2)) -> 0 | M27: =SQRT((1/6)*(((PM!D362/60)-F27)^2+((PM!D363/60)-F27)^2+((PM!D364/60)-F27)^2)) -> 0 | N27: 0.7 | O27: 1 | Q27: =((I27^2)*((L27^2)+(N27^2)+(O27^2)+((J27*M27)^2))) -> #NUM! | R27: =IFERROR(Q27,0) -> 0
D28: 24 | E28: =PM!D371 -> 0 | F28: =PM!D384 -> 0 | G28: =PM!D384 -> 0 | H28: =PM!K381 -> 0 | I28: =((F28/8)*10^(0.1*(G28-F2))) -> #NUM! | J28: =4.34*(I28/F28) -> #NUM! | K28: =(PM!G378+PM!G379+PM!G380)/3 -> 0 | L28: =SQRT((1/6)*((PM!G378-K28)^2+(PM!G379-K28)^2+(PM!G380-K28)^2)) -> 0 | M28: =SQRT((1/6)*(((PM!D378/60)-F28)^2+((PM!D379/60)-F28)^2+((PM!D380/60)-F28)^2)) -> 0 | N28: 0.7 | O28: 1 | Q28: =((I28^2)*((L28^2)+(N28^2)+(O28^2)+((J28*M28)^2))) -> #NUM! | R28: =IFERROR(Q28,0) -> 0
D29: 25 | E29: =PM!D387 -> 0 | F29: =PM!D400 -> 0 | G29: =PM!D400 -> 0 | H29: =PM!K397 -> 0 | I29: =((F29/8)*10^(0.1*(G29-F2))) -> #NUM! | J29: =4.34*(I29/F29) -> #NUM! | K29: =(PM!G394+PM!G395+PM!G396)/3 -> 0 | L29: =SQRT((1/6)*((PM!G394-K29)^2+(PM!G395-K29)^2+(PM!G396-K29)^2)) -> 0 | M29: =SQRT((1/6)*(((PM!D394/60)-F29)^2+((PM!D395/60)-F29)^2+((PM!D396/60)-F29)^2)) -> 0 | N29: 0.7 | O29: 1 | Q29: =((I29^2)*((L29^2)+(N29^2)+(O29^2)+((J29*M29)^2))) -> #NUM! | R29: =IFERROR(Q29,0) -> 0
D30: 26 | E30: =PM!D403 -> 0 | F30: =PM!D416 -> 0 | G30: =PM!D416 -> 0 | H30: =PM!K413 -> 0 | I30: =((F30/8)*10^(0.1*(G30-F2))) -> #NUM! | J30: =4.34*(I30/F30) -> #NUM! | K30: =(PM!G410+PM!G411+PM!G412)/3 -> 0 | L30: =SQRT((1/6)*((PM!G410-K30)^2+(PM!G411-K30)^2+(PM!G412-K30)^2)) -> 0 | M30: =SQRT((1/6)*(((PM!D410/60)-F30)^2+((PM!D411/60)-F30)^2+((PM!D412/60)-F30)^2)) -> 0 | N30: 0.7 | O30: 1 | Q30: =((I30^2)*((L30^2)+(N30^2)+(O30^2)+((J30*M30)^2))) -> #NUM! | R30: =IFERROR(Q30,0) -> 0
D31: 27 | E31: =PM!D419 -> 0 | F31: =PM!D432 -> 0 | G31: =PM!D432 -> 0 | H31: =PM!K429 -> 0 | I31: =((F31/8)*10^(0.1*(G31-F2))) -> #NUM! | J31: =4.34*(I31/F31) -> #NUM! | K31: =(PM!G426+PM!G427+PM!G428)/3 -> 0 | L31: =SQRT((1/6)*((PM!G426-K31)^2+(PM!G427-K31)^2+(PM!G428-K31)^2)) -> 0 | M31: =SQRT((1/6)*(((PM!D426/60)-F31)^2+((PM!D427/60)-F31)^2+((PM!D428/60)-F31)^2)) -> 0 | N31: 0.7 | O31: 1 | Q31: =((I31^2)*((L31^2)+(N31^2)+(O31^2)+((J31*M31)^2))) -> #NUM! | R31: =IFERROR(Q31,0) -> 0
D32: 28 | E32: =PM!D435 -> 0 | F32: =PM!D448 -> 0 | G32: =PM!D448 -> 0 | H32: =PM!K445 -> 0 | I32: =((F32/8)*10^(0.1*(G32-F2))) -> #NUM! | J32: =4.34*(I32/F32) -> #NUM! | K32: =(PM!G442+PM!G443+PM!G444)/3 -> 0 | L32: =SQRT((1/6)*((PM!G442-K32)^2+(PM!G443-K32)^2+(PM!G444-K32)^2)) -> 0 | M32: =SQRT((1/6)*(((PM!D442/60)-F32)^2+((PM!D443/60)-F32)^2+((PM!D444/60)-F32)^2)) -> 0 | N32: 0.7 | O32: 1 | Q32: =((I32^2)*((L32^2)+(N32^2)+(O32^2)+((J32*M32)^2))) -> #NUM! | R32: =IFERROR(Q32,0) -> 0
D33: 29 | E33: =PM!D451 -> 0 | F33: =PM!D464 -> 0 | G33: =PM!D464 -> 0 | H33: =PM!K461 -> 0 | I33: =((F33/8)*10^(0.1*(G33-F2))) -> #NUM! | J33: =4.34*(I33/F33) -> #NUM! | K33: =(PM!G458+PM!G459+PM!G460)/3 -> 0 | L33: =SQRT((1/6)*((PM!G458-K33)^2+(PM!G459-K33)^2+(PM!G460-K33)^2)) -> 0 | M33: =SQRT((1/6)*(((PM!D458/60)-F33)^2+((PM!D459/60)-F33)^2+((PM!D460/60)-F33)^2)) -> 0 | N33: 0.7 | O33: 1 | Q33: =((I33^2)*((L33^2)+(N33^2)+(O33^2)+((J33*M33)^2))) -> #NUM! | R33: =IFERROR(Q33,0) -> 0
D34: 30 | E34: =PM!D467 -> 0 | F34: =PM!D480 -> 0 | G34: =PM!D480 -> 0 | H34: =PM!K477 -> 0 | I34: =((F34/8)*10^(0.1*(G34-F2))) -> #NUM! | J34: =4.34*(I34/F34) -> #NUM! | K34: =(PM!G474+PM!G475+PM!G476)/3 -> 0 | L34: =SQRT((1/6)*((PM!G474-K34)^2+(PM!G475-K34)^2+(PM!G476-K34)^2)) -> 0 | M34: =SQRT((1/6)*(((PM!D474/60)-F34)^2+((PM!D475/60)-F34)^2+((PM!D476/60)-F34)^2)) -> 0 | N34: 0.7 | O34: 1 | Q34: =((I34^2)*((L34^2)+(N34^2)+(O34^2)+((J34*M34)^2))) -> #NUM! | R34: =IFERROR(Q34,0) -> 0
R35: u2(LEX,8h)
R36: =SUM(R5:R34) -> 0
R38: u(LEX,8h)
R39: =SQRT(R36) -> 0
R41: U(LEX,8h) [dBA]
R42: =1.65*R39 -> 0

Sheet Tab. riassuntiva LEX,8h
B3: Gruppo Omogeneo | C3: LEX,8h [dBA] | D3: U(LEX,8h) [dBA] | E3: L'EX,8h [dBA] | F3: Ppeak max [dBC]
B4: =PM!B10 -> 0 | C4: ='Calcolo incertezza U(LEX,8h)'!F2 -> #NUM! | D4: ='Calcolo incertezza U(LEX,8h)'!R42 -> 0 | E4: =C4+D4 -> #NUM! | F4: =MAX(PM!K13,PM!K29,PM!K45,PM!K61,PM!K77,PM!K93,PM!K109,PM!K125,PM!K141,PM!K157,PM!K173,PM!K189,PM!K205,PM!K221,PM!K237,PM!K253,PM!K269,PM!K285,PM!K301,PM!K317,PM!K333,PM!K349,PM!K365,PM!K381,PM!K397,PM!K413,PM!K429,PM!K445,PM!K461,PM!K477,) -> 0

Sheet L'EX,8hmax esp. giorn. con DPI
B2: Gruppo omogeneo | D2: =PM!B10 -> 0
B3: METODO DI CALCOLO SNR EN UNI 458/2005 | H3: Valore SNR | J3: Lact = 80 dBA
B4: Postazione | C4: Attrezzature di lavoro e/o rumore di fondo ambientale | D4: LAeq,m [dBA] | E4: LCeq,m [dBC] | F4: β | G4: L'Aeq,m [dBA] | H4: Stima della protezione | I4: Tm [ore] | J4: L'EX,8h SNR [dBA] | K4: U(LEX,8h) [dBA] | L4: L'EX,8hmax SNR [dBA]
B5: 1 | C5: ='Calcolo incertezza U(LEX,8h)'!E5 -> 0 | D5: =PM!G13 -> 0 | E5: =IF(PM!G13>80,PM!I13,"") | F5: 0.75 | G5: =IF(D5>80,(E5-I$3*F5),P5) -> 0 | H5: =IF(E5="","",IF(G5>80,"Insufficiente",IF(OR(G5>75,G5=80),"Accettabile",IF(OR(G5=75,G5>70),"Buona",IF(OR(G5=70,G5>65),"Accettabile",IF(OR(G5=65,G5>0),"Iperprotezione",IF(OR(G5=0,G5<0),""))))))) | I5: =PM!D16 -> 0 | J5: =10*(LOG10((I5/8)*10^(0.1*G5)+(I6/8)*10^(0.1*G6)+(I7/8)*10^(0.1*G7)+(I8/8)*10^(0.1*G8)+(I9/8)*10^(0.1*G9)+(I10/8)*10^(0.1*G10)+(I11/8)*10^(0.1*G11)+(I12/8)*10^(0.1*G12)+(I13/8)*10^(0.1*G13)+(I14/8)*10^(0.1*G14)+(I15/8)*10^(0.1*G15)+(I16/8)*10^(0.1*G16)+(I17/8)*10^(0.1*G17)+(I18/8)*10^(0.1*G18)+(I19/8)*10^(0.1*G19)+(I20/8)*10^(0.1*G20)+(I21/8)*10^(0.1*G21)+(I22/8)*10^(0.1*G22)+(I23/8)*10^(0.1*G23)+(I24/8)*10^(0.1*G24)+(I25/8)*10^(0.1*G25)+(I26/8)*10^(0.1*G26)+(I27/8)*10^(0.1*G27)+(I28/8)*10^(0.1*G28)+(I29/8)*10^(0.1*G29)+(I30/8)*10^(0.1*G30)+(I31/8)*10^(0.1*G31)+(I32/8)*10^(0.1*G32)+(I33/8)*10^(0.1*G33)+(I34/8)*10^(0.1*G34))) -> #NUM! | K5: ='Tab. riassuntiva LEX,8h'!D4 -> 0 | L5: =J5+K5 -> #NUM! | P5: =D5 -> 0
B6: 2 | C6: ='Calcolo incertezza U(LEX,8h)'!E6 -> 0 | D6: =PM!G29 -> 0 | E6: =IF(PM!G29>80,PM!I29,"") | F6: 0.75 | G6: =IF(D6>80,(E6-I$3*F6),P6) -> 0 | H6: =IF(E6="","",IF(G6>80,"Insufficiente",IF(OR(G6>75,G6=80),"Accettabile",IF(OR(G6=75,G6>70),"Buona",IF(OR(G6=70,G6>65),"Accettabile",IF(OR(G6=65,G6>0),"Iperprotezione",IF(OR(G6=0,G6<0),""))))))) | I6: =PM!D32 -> 0 | P6: =D6 -> 0
B7: 3 | C7: ='Calcolo incertezza U(LEX,8h)'!E7 -> 0 | D7: =PM!G45 -> 0 | E7: =IF(PM!G45>80,PM!I45,"") | F7: 0.75 | G7: =IF(D7>80,(E7-I$3*F7),P7) -> 0 | H7: =IF(E7="","",IF(G7>80,"Insufficiente",IF(OR(G7>75,G7=80),"Accettabile",IF(OR(G7=75,G7>70),"Buona",IF(OR(G7=70,G7>65),"Accettabile",IF(OR(G7=65,G7>0),"Iperprotezione",IF(OR(G7=0,G7<0),""))))))) | I7: =PM!D48 -> 0 | P7: =D7 -> 0
B8: 4 | C8: ='Calcolo incertezza U(LEX,8h)'!E8 -> 0 | D8: =PM!G61 -> 0 | E8: =IF(PM!G61>80,PM!I61,"") | F8: 0.75 | G8: =IF(D8>80,(E8-I$3*F8),P8) -> 0 | H8: =IF(E8="","",IF(G8>80,"Insufficiente",IF(OR(G8>75,G8=80),"Accettabile",IF(OR(G8=75,G8>70),"Buona",IF(OR(G8=70,G8>65),"Accettabile",IF(OR(G8=65,G8>0),"Iperprotezione",IF(OR(G8=0,G8<0),""))))))) | I8: =PM!D64 -> 0 | P8: =D8 -> 0
B9: 5 | C9: ='Calcolo incertezza U(LEX,8h)'!E9 -> 0 | D9: =PM!G77 -> 0 | E9: =IF(PM!G77>80,PM!I77,"") | F9: 0.75 | G9: =IF(D9>80,(E9-I$3*F9),P9) -> 0 | H9: =IF(E9="","",IF(G9>80,"Insufficiente",IF(OR(G9>75,G9=80),"Accettabile",IF(OR(G9=75,G9>70),"Buona",IF(OR(G9=70,G9>65),"Accettabile",IF(OR(G9=65,G9>0),"Iperprotezione",IF(OR(G9=0,G9<0),""))))))) | I9: =PM!D80 -> 0 | P9: =D9 -> 0
B10: 6 | C10: ='Calcolo incertezza U(LEX,8h)'!E10 -> 0 | D10: =PM!G93 -> 0 | E10: =IF(PM!G93>80,PM!I93,"") | F10: 0.75 | G10: =IF(D10>80,(E10-I$3*F10),P10) -> 0 | H10: =IF(E10="","",IF(G10>80,"Insufficiente",IF(OR(G10>75,G10=80),"Accettabile",IF(OR(G10=75,G10>70),"Buona",IF(OR(G10=70,G10>65),"Accettabile",IF(OR(G10=65,G10>0),"Iperprotezione",IF(OR(G10=0,G10<0),""))))))) | I10: =PM!D96 -> 0 | P10: =D10 -> 0
B11: 7 | C11: ='Calcolo incertezza U(LEX,8h)'!E11 -> 0 | D11: =PM!G109 -> 0 | E11: =IF(PM!G109>80,PM!I109,"") | F11: 0.75 | G11: =IF(D11>80,(E11-I$3*F11),P11) -> 0 | H11: =IF(E11="","",IF(G11>80,"Insufficiente",IF(OR(G11>75,G11=80),"Accettabile",IF(OR(G11=75,G11>70),"Buona",IF(OR(G11=70,G11>65),"Accettabile",IF(OR(G11=65,G11>0),"Iperprotezione",IF(OR(G11=0,G11<0),""))))))) | I11: =PM!D112 -> 0 | P11: =D11 -> 0
B12: 8 | C12: ='Calcolo incertezza U(LEX,8h)'!E12 -> 0 | D12: =PM!G125 -> 0 | E12: =IF(PM!G125>80,PM!I125,"") | F12: 0.75 | G12: =IF(D12>80,(E12-I$3*F12),P12) -> 0 | H12: =IF(E12="","",IF(G12>80,"Insufficiente",IF(OR(G12>75,G12=80),"Accettabile",IF(OR(G12=75,G12>70),"Buona",IF(OR(G12=70,G12>65),"Accettabile",IF(OR(G12=65,G12>0),"Iperprotezione",IF(OR(G12=0,G12<0),""))))))) | I12: =PM!D128 -> 0 | P12: =D12 -> 0
B13: 9 | C13: ='Calcolo incertezza U(LEX,8h)'!E13 -> 0 | D13: =PM!G141 -> 0 | E13: =IF(PM!G141>80,PM!I141,"") | F13: 0.75 | G13: =IF(D13>80,(E13-I$3*F13),P13) -> 0 | H13: =IF(E13="","",IF(G13>80,"Insufficiente",IF(OR(G13>75,G13=80),"Accettabile",IF(OR(G13=75,G13>70),"Buona",IF(OR(G13=70,G13>65),"Accettabile",IF(OR(G13=65,G13>0),"Iperprotezione",IF(OR(G13=0,G13<0),""))))))) | I13: =PM!D144 -> 0 | P13: =D13 -> 0
B14: 10 | C14: ='Calcolo incertezza U(LEX,8h)'!E14 -> 0 | D14: =PM!G157 -> 0 | E14: =IF(PM!G157>80,PM!I157,"") | F14: 0.75 | G14: =IF(D14>80,(E14-I$3*F14),P14) -> 0 | H14: =IF(E14="","",IF(G14>80,"Insufficiente",IF(OR(G14>75,G14=80),"Accettabile",IF(OR(G14=75,G14>70),"Buona",IF(OR(G14=70,G14>65),"Accettabile",IF(OR(G14=65,G14>0),"Iperprotezione",IF(OR(G14=0,G14<0),""))))))) | I14: =PM!D160 -> 0 | P14: =D14 -> 0
B15: 11 | C15: ='Calcolo incertezza U(LEX,8h)'!E15 -> 0 | D15: =PM!G173 -> 0 | E15: =IF(PM!G173>80,PM!I173,"") | F15: 0.75 | G15: =IF(D15>80,(E15-I$3*F15),P15) -> 0 | H15: =IF(E15="","",IF(G15>80,"Insufficiente",IF(OR(G15>75,G15=80),"Accettabile",IF(OR(G15=75,G15>70),"Buona",IF(OR(G15=70,G15>65),"Accettabile",IF(OR(G15=65,G15>0),"Iperprotezione",IF(OR(G15=0,G15<0),""))))))) | I15: =PM!D176 -> 0 | P15: =D15 -> 0
B16: 12 | C16: ='Calcolo incertezza U(LEX,8h)'!E16 -> 0 | D16: =PM!G189 -> 0 | E16: =IF(PM!G189>80,PM!I189,"") | F16: 0.75 | G16: =IF(D16>80,(E16-I$3*F16),P16) -> 0 | H16: =IF(E16="","",IF(G16>80,"Insufficiente",IF(OR(G16>75,G16=80),"Accettabile",IF(OR(G16=75,G16>70),"Buona",IF(OR(G16=70,G16>65),"Accettabile",IF(OR(G16=65,G16>0),"Iperprotezione",IF(OR(G16=0,G16<0),""))))))) | I16: =PM!D192 -> 0 | P16: =D16 -> 0
B17: 13 | C17: ='Calcolo incertezza U(LEX,8h)'!E17 -> 0 | D17: =PM!G205 -> 0 | E17: =IF(PM!G205>80,PM!I205,"") | F17: 0.75 | G17: =IF(D17>80,(E17-I$3*F17),P17) -> 0 | H17: =IF(E17="","",IF(G17>80,"Insufficiente",IF(OR(G17>75,G17=80),"Accettabile",IF(OR(G17=75,G17>70),"Buona",IF(OR(G17=70,G17>65),"Accettabile",IF(OR(G17=65,G17>0),"Iperprotezione",IF(OR(G17=0,G17<0),""))))))) | I17: =PM!D208 -> 0 | P17: =D17 -> 0
B18: 14 | C18: ='Calcolo incertezza U(LEX,8h)'!E18 -> 0 | D18: =PM!G221 -> 0 | E18: =IF(PM!G221>80,PM!I221,"") | F18: 0.75 | G18: =IF(D18>80,(E18-I$3*F18),P18) -> 0 | H18: =IF(E18="","",IF(G18>80,"Insufficiente",IF(OR(G18>75,G18=80),"Accettabile",IF(OR(G18=75,G18>70),"Buona",IF(OR(G18=70,G18>65),"Accettabile",IF(OR(G18=65,G18>0),"Iperprotezione",IF(OR(G18=0,G18<0),""))))))) | I18: =PM!D224 -> 0 | P18: =D18 -> 0
B19: 15 | C19: ='Calcolo incertezza U(LEX,8h)'!E19 -> 0 | D19: =PM!G237 -> 0 | E19: =IF(PM!G237>80,PM!I237,"") | F19: 0.75 | G19: =IF(D19>80,(E19-I$3*F19),P19) -> 0 | H19: =IF(E19="","",IF(G19>80,"Insufficiente",IF(OR(G19>75,G19=80),"Accettabile",IF(OR(G19=75,G19>70),"Buona",IF(OR(G19=70,G19>65),"Accettabile",IF(OR(G19=65,G19>0),"Iperprotezione",IF(OR(G19=0,G19<0),""))))))) | I19: =PM!D240 -> 0 | P19: =D19 -> 0
B20: 16 | C20: ='Calcolo incertezza U(LEX,8h)'!E20 -> 0 | D20: =PM!G253 -> 0 | E20: =IF(PM!G253>80,PM!I253,"") | F20: 0.75 | G20: =IF(D20>80,(E20-I$3*F20),P20) -> 0 | H20: =IF(E20="","",IF(G20>80,"Insufficiente",IF(OR(G20>75,G20=80),"Accettabile",IF(OR(G20=75,G20>70),"Buona",IF(OR(G20=70,G20>65),"Accettabile",IF(OR(G20=65,G20>0),"Iperprotezione",IF(OR(G20=0,G20<0),""))))))) | I20: =PM!D256 -> 0 | P20: =D20 -> 0
B21: 17 | C21: ='Calcolo incertezza U(LEX,8h)'!E21 -> 0 | D21: =PM!G269 -> 0 | E21: =IF(PM!G269>80,PM!I269,"") | F21: 0.75 | G21: =IF(D21>80,(E21-I$3*F21),P21) -> 0 | H21: =IF(E21="","",IF(G21>80,"Insufficiente",IF(OR(G21>75,G21=80),"Accettabile",IF(OR(G21=75,G21>70),"Buona",IF(OR(G21=70,G21>65),"Accettabile",IF(OR(G21=65,G21>0),"Iperprotezione",IF(OR(G21=0,G21<0),""))))))) | I21: =PM!D272 -> 0 | P21: =D21 -> 0
B22: 18 | C22: ='Calcolo incertezza U(LEX,8h)'!E22 -> 0 | D22: =PM!G285 -> 0 | E22: =IF(PM!G285>80,PM!I285,"") | F22: 0.75 | G22: =IF(D22>80,(E22-I$3*F22),P22) -> 0 | H22: =IF(E22="","",IF(G22>80,"Insufficiente",IF(OR(G22>75,G22=80),"Accettabile",IF(OR(G22=75,G22>70),"Buona",IF(OR(G22=70,G22>65),"Accettabile",IF(OR(G22=65,G22>0),"Iperprotezione",IF(OR(G22=0,G22<0),""))))))) | I22: =PM!D288 -> 0 | P22: =D22 -> 0
B23: 19 | C23: ='Calcolo incertezza U(LEX,8h)'!E23 -> 0 | D23: =PM!G301 -> 0 | E23: =IF(PM!G301>80,PM!I301,"") | F23: 0.75 | G23: =IF(D23>80,(E23-I$3*F23),P23) -> 0 | H23: =IF(E23="","",IF(G23>80,"Insufficiente",IF(OR(G23>75,G23=80),"Accettabile",IF(OR(G23=75,G23>70),"Buona",IF(OR(G23=70,G23>65),"Accettabile",IF(OR(G23=65,G23>0),"Iperprotezione",IF(OR(G23=0,G23<0),""))))))) | I23: =PM!D304 -> 0 | P23: =D23 -> 0
B24: 20 | C24: ='Calcolo incertezza U(LEX,8h)'!E24 -> 0 | D24: =PM!G317 -> 0 | E24: =IF(PM!G317>80,PM!I317,"") | F24: 0.75 | G24: =IF(D24>80,(E24-I$3*F24),P24) -> 0 | H24: =IF(E24="","",IF(G24>80,"Insufficiente",IF(OR(G24>75,G24=80),"Accettabile",IF(OR(G24=75,G24>70),"Buona",IF(OR(G24=70,G24>65),"Accettabile",IF(OR(G24=65,G24>0),"Iperprotezione",IF(OR(G24=0,G24<0),""))))))) | I24: =PM!D320 -> 0 | P24: =D24 -> 0
B25: 21 | C25: ='Calcolo incertezza U(LEX,8h)'!E25 -> 0 | D25: =PM!G333 -> 0 | E25: =IF(PM!G333>80,PM!I333,"") | F25: 0.75 | G25: =IF(D25>80,(E25-I$3*F25),P25) -> 0 | H25: =IF(E25="","",IF(G25>80,"Insufficiente",IF(OR(G25>75,G25=80),"Accettabile",IF(OR(G25=75,G25>70),"Buona",IF(OR(G25=70,G25>65),"Accettabile",IF(OR(G25=65,G25>0),"Iperprotezione",IF(OR(G25=0,G25<0),""))))))) | I25: =PM!D336 -> 0 | P25: =D25 -> 0
B26: 22 | C26: ='Calcolo incertezza U(LEX,8h)'!E26 -> 0 | D26: =PM!G349 -> 0 | E26: =IF(PM!G349>80,PM!I349,"") | F26: 0.75 | G26: =IF(D26>80,(E26-I$3*F26),P26) -> 0 | H26: =IF(E26="","",IF(G26>80,"Insufficiente",IF(OR(G26>75,G26=80),"Accettabile",IF(OR(G26=75,G26>70),"Buona",IF(OR(G26=70,G26>65),"Accettabile",IF(OR(G26=65,G26>0),"Iperprotezione",IF(OR(G26=0,G26<0),""))))))) | I26: =PM!D352 -> 0 | P26: =D26 -> 0
B27: 23 | C27: ='Calcolo incertezza U(LEX,8h)'!E27 -> 0 | D27: =PM!G365 -> 0 | E27: =IF(PM!G365>80,PM!I365,"") | F27: 0.75 | G27: =IF(D27>80,(E27-I$3*F27),P27) -> 0 | H27: =IF(E27="","",IF(G27>80,"Insufficiente",IF(OR(G27>75,G27=80),"Accettabile",IF(OR(G27=75,G27>70),"Buona",IF(OR(G27=70,G27>65),"Accettabile",IF(OR(G27=65,G27>0),"Iperprotezione",IF(OR(G27=0,G27<0),""))))))) | I27: =PM!D368 -> 0 | P27: =D27 -> 0
B28: 24 | C28: ='Calcolo incertezza U(LEX,8h)'!E28 -> 0 | D28: =PM!G381 -> 0 | E28: =IF(PM!G381>80,PM!I381,"") | F28: 0.75 | G28: =IF(D28>80,(E28-I$3*F28),P28) -> 0 | H28: =IF(E28="","",IF(G28>80,"Insufficiente",IF(OR(G28>75,G28=80),"Accettabile",IF(OR(G28=75,G28>70),"Buona",IF(OR(G28=70,G28>65),"Accettabile",IF(OR(G28=65,G28>0),"Iperprotezione",IF(OR(G28=0,G28<0),""))))))) | I28: =PM!D384 -> 0 | P28: =D28 -> 0
B29: 25 | C29: ='Calcolo incertezza U(LEX,8h)'!E29 -> 0 | D29: =PM!G397 -> 0 | E29: =IF(PM!G397>80,PM!I397,"") | F29: 0.75 | G29: =IF(D29>80,(E29-I$3*F29),P29) -> 0 | H29: =IF(E29="","",IF(G29>80,"Insufficiente",IF(OR(G29>75,G29=80),"Accettabile",IF(OR(G29=75,G29>70),"Buona",IF(OR(G29=70,G29>65),"Accettabile",IF(OR(G29=65,G29>0),"Iperprotezione",IF(OR(G29=0,G29<0),""))))))) | I29: =PM!D400 -> 0 | P29: =D29 -> 0
B30: 26 | C30: ='Calcolo incertezza U(LEX,8h)'!E30 -> 0 | D30: =PM!G413 -> 0 | E30: =IF(PM!G413>80,PM!I413,"") | F30: 0.75 | G30: =IF(D30>80,(E30-I$3*F30),P30) -> 0 | H30: =IF(E30="","",IF(G30>80,"Insufficiente",IF(OR(G30>75,G30=80),"Accettabile",IF(OR(G30=75,G30>70),"Buona",IF(OR(G30=70,G30>65),"Accettabile",IF(OR(G30=65,G30>0),"Iperprotezione",IF(OR(G30=0,G30<0),""))))))) | I30: =PM!D416 -> 0 | P30: =D30 -> 0
B31: 27 | C31: ='Calcolo incertezza U(LEX,8h)'!E31 -> 0 | D31: =PM!G429 -> 0 | E31: =IF(PM!G429>80,PM!I429,"") | F31: 0.75 | G31: =IF(D31>80,(E31-I$3*F31),P31) -> 0 | H31: =IF(E31="","",IF(G31>80,"Insufficiente",IF(OR(G31>75,G31=80),"Accettabile",IF(OR(G31=75,G31>70),"Buona",IF(OR(G31=70,G31>65),"Accettabile",IF(OR(G31=65,G31>0),"Iperprotezione",IF(OR(G31=0,G31<0),""))))))) | I31: =PM!D432 -> 0 | P31: =D31 -> 0
B32: 28 | C32: ='Calcolo incertezza U(LEX,8h)'!E32 -> 0 | D32: =PM!G445 -> 0 | E32: =IF(PM!G445>80,PM!I445,"") | F32: 0.75 | G32: =IF(D32>80,(E32-I$3*F32),P32) -> 0 | H32: =IF(E32="","",IF(G32>80,"Insufficiente",IF(OR(G32>75,G32=80),"Accettabile",IF(OR(G32=75,G32>70),"Buona",IF(OR(G32=70,G32>65),"Accettabile",IF(OR(G32=65,G32>0),"Iperprotezione",IF(OR(G32=0,G32<0),""))))))) | I32: =PM!D448 -> 0 | P32: =D32 -> 0
B33: 29 | C33: ='Calcolo incertezza U(LEX,8h)'!E33 -> 0 | D33: =PM!G461 -> 0 | E33: =IF(PM!G461>80,PM!I461,"") | F33: 0.75 | G33: =IF(D33>80,(E33-I$3*F33),P33) -> 0 | H33: =IF(E33="","",IF(G33>80,"Insufficiente",IF(OR(G33>75,G33=80),"Accettabile",IF(OR(G33=75,G33>70),"Buona",IF(OR(G33=70,G33>65),"Accettabile",IF(OR(G33=65,G33>0),"Iperprotezione",IF(OR(G33=0,G33<0),""))))))) | I33: =PM!D464 -> 0 | P33: =D33 -> 0
B34: 30 | C34: ='Calcolo incertezza U(LEX,8h)'!E34 -> 0 | D34: =PM!G477 -> 0 | E34: =IF(PM!G477>80,PM!I477,"") | F34: 0.75 | G34: =IF(D34>80,(E34-I$3*F34),P34) -> 0 | H34: =IF(E34="","",IF(G34>80,"Insufficiente",IF(OR(G34>75,G34=80),"Accettabile",IF(OR(G34=75,G34>70),"Buona",IF(OR(G34=70,G34>65),"Accettabile",IF(OR(G34=65,G34>0),"Iperprotezione",IF(OR(G34=0,G34<0),""))))))) | I34: =PM!D480 -> 0 | P34: =D34 -> 0

Sheet Tab. riassuntiva L'EX,8h
B3: Gruppo Omogeneo | C3: LEX,8h [dBA] | D3: L'EX,8h SNR [dBA] | E3: U(LEX,8h) [dBA] | F3: L'EX,8hmax SNR [dBA] | G3: Ppeak max [dBC]
B4: =PM!B10 -> 0 | C4: ='Calcolo incertezza U(LEX,8h)'!F2 -> #NUM! | D4: ='L''EX,8hmax esp. giorn. con DPI'!J5 -> #NUM! | E4: ='L''EX,8hmax esp. giorn. con DPI'!K5 -> 0 | F4: ='L''EX,8hmax esp. giorn. con DPI'!L5 -> #NUM! | G4: ='Tab. riassuntiva LEX,8h'!F4 -> 0
